Workbook
Name Aggr_2021: Intentionally_produced_MPs!$J$63
Name In_EU_2018: Agriculture!$E$4
Name In_EU_2019: Agriculture!$E$5
Name IN_NL_2018_high: Agriculture!$E$23
Name In_NL_2018_low: Agriculture!$E$22
Name IN_NL_2019_high: Agriculture!$E$25
Name IN_NL_2019_low: Agriculture!$E$24
Name Intentional_Agr_EU_2020: Agriculture!$B$232
Name Intentional_Agr_NL_2020: Agriculture!$C$232
Name OECD_ref_2018: 'Input projections'!$B$40
Name OECD_ref_2019: 'Input projections'!$B$41
Name OIL_GAS_2020: Intentionally_produced_MPs!$J$65
Name POP_coef_2020: Intentionally_produced_MPs!$J$61
Name Synthetic_fraction: Clothing_update!#REF!

Sheet README
A1: Explanation of the sheets in this document
A2: Sheet name | B2: Description | D2: More detailed info
A3: Data Quality Indicators | B3: Descriptions of the scores of the data quality indicators | D3: Input values and transfer coefficient values are assigned a 'data quality indicator' for five categories. The indicator scores range from 1 (very good) to 4 (very poor). The table is adopted from Kawecki et al. (2019) can be used to assign the correct data quality indicator score to each input and transfer coefficient value.
A4: Materials | B4: All polymers that are considered in this study
A5: Input_EU | B5: Input data in kton per year at EU scale for the input compartments | D5: The 13 input compartments are: Packaging, Building and Construction, Automotive (product sector), EEE (product sector), Agriculture, Clothing (product sector), Household textiles (product sector), Technical textiles, Other plastic products (product sector), Paint, Intentionally produced microparticles, Domestic primary plastic production, Import of primary plastics
A6: Input_NL | B6: Input data in kton per year at NL scale for the input compartments | D6: The 13 input compartments are: Packaging, Building and Construction, Automotive (product sector), EEE (product sector), Agriculture, Clothing (product sector), Household textiles (product sector), Technical textiles, Other plastic products (product sector), Paint, Intentionally produced microparticles, Domestic primary plastic production, Import of primary plastics
A7: Transfer coefficients | B7: Transfer coefficients (0 - 1) that describe the distribution of microplastics from one to another compartment between compartments | D7: Plastics are transferred from one compartment to the other. How the plastics are distributed amongst the next compartments is defined by the transfer coefficients. The sum of the transfer coefficients for each compartment must equal 1 (mass balance: no plastics are lost)
A8: Lifetimes_pairs | B8: The lifetime categories that are assgined to each stock compartment | D8: Plastic producs have a lifetime, which refers to the length of time for which it is estimated that the product will be used by the consumer. This table links each stock compartment to a lifetime category.
A9: Lifetimes | B9: The lifetime (or discarding) funtion for each lifetime category (for the first 200 years) | D9: The fraction of the plastic product that flows to the next compartment(s) in the first 200 years after the product is consumed.
A10: Compartments | B10: List of all compartments included in this study | D10: x
A11: Compartments_Kawecki&Nowack19 | B11: List of all compartments included in the study from Kawecki and Nowack (2019) | D11: x
A12: Compartments_Added_by_RIVM_TNO | B12: List of all compartments that were not inlcuded in the study from Kawecki and Nowack (2019) and that have been added by the RIVM/TNO team in 2023 | D12: x
A13: Check_Compartments | B13: Check sheet | D13: Checks all input compartments. Checks if input compartments only have an outgoing flow (from). Checks if flow compartments have and in- and outgoing flow (from & to). Checks if sink compartments only have an ingoing flow (to).
A14: Textiles | B14: Calculation of the input and transfer coefficients of textile related compartments | D14: The cells that are highlighted in green contain the values that are used in the 'Input_EU', 'Input_NL', or 'Transfer coefficient' sheet.
A15: Intentionally produced microparticles | B15: Calculation of the input and transfer coefficients of intentionally produced microparticle related compartments | D15: The cells that are highlighted in green contain the values that are used in the 'Input_EU', 'Input_NL', or 'Transfer coefficient' sheet.
A16: Packaging | B16: Calculation of the input and transfer coefficients of packaging related compartments | D16: The cells that are highlighted in green contain the values that are used in the 'Input_EU', 'Input_NL', or 'Transfer coefficient' sheet.
A19: Sources used in this document | B19: Full citation
A20: Kawecki & Nowack (2019) | B20: Kawecki, D., & Nowack, B. (2019). Polymer-specific modeling of the environmental emissions of seven commodity plastics as macro-and microplastics. Environmental science & technology, 53(16), 9664-9676.
A21: Kawecki et al. (2021) | B21: Kawecki, D., Wu, Q., Gonçalves, J. S., & Nowack, B. (2021). Polymer-specific dynamic probabilistic material flow analysis of seven polymers in Europe from 1950 to 2016. Resources, Conservation and Recycling, 173, 105733.

Sheet Version
A1: Date | B1: Adjustment
A2: 28-1-2025 | B2: Added Clothing_update tab

Sheet Data Quality Indicators
A1: Category | B1: Abbreviation | C1: Very Good | D1: Good | E1: Poor | F1: Very Poor
A2: Score | C2: DQIS = 1 | D2: DQIS = 2 | E2: DQIS = 3 | F2: DQIS = 4
A3: Geographical representativeness | B3: Geo (NL or EU) | C3: Same region (for EU: EU28 and EU28+2 qualify, for NL: CBS data qualifies) | D3: Socioeconomically similar region (i.e. Europe vs. Switzerland) | E3: Socioeconomically different region (i.e. USA vs. Europe) | F3: Socioeconomically very different region (i.e. World vs. Europe)
A4: Temporal representativeness | B4: Temp | C4: Same year (2019 reference year) | D4: 1-3 year difference (2016-2018, 2020-2022) | E4: 4-10 year difference (2009-2015) | F4: More than 10 year difference (prior to 2009)
A5: Material representativeness | B5: Mat | C5: Same polymer | D5: Same polymer datum corrected with data for all polymers | E5: Data for a different polymer, or for plastic as a whole, or including similar materials | F5: Including non-similar materials
A6: (Technical) Completeness | B6: Tech | C6: Includes all relevant processes/flows | D6: Includes main processes/flows | E6: Partially including main processes/flows | F6: Important processes/flows are missing
A7: Source reliability | B7: Rel | C7: Official report /peer reviewed documentation | D7: Martket reports and other reports / Public databases | E7: Qualified estimate | F7: Non-qualified estimate

Sheet Materials
A1: Name
A2: LDPE
A3: HDPE
A4: PP
A5: PS
A6: EPS
A7: PVC
A8: PET
A9: RUBBER
A10: PUR
A11: ABS
A12: PA
... A16: Acryl

Sheet Input_NL
A1: Compartment | B1: Year | C1: Material | D1: Data (kt) | E1: Source | F1: Geo | G1: Temp | H1: Mat | I1: Tech | J1: Rel | K1: Spread | L1: Codes and comments
A2: =Agriculture!A47 -> Agriculture | B2: =Agriculture!C47 -> 2019 | C2: =Agriculture!D47 -> LDPE | D2: =Agriculture!E47 -> 40.881766 | E2: =Agriculture!F47 -> Combined from TNO Sieger Henke and Statistics - APE Europe [WWW Document], n.d. URL https://web.archive.org/web/20230930160250/https://apeeurope.eu/statistics/ (accessed 3.27.24). Using 6.7% conversion to NL | F2: 2 | G2: 1 | H2: 2 | I2: 1 | J2: 2 | K2: =IF( OR( ISBLANK(F2),ISBLANK(G2), ISBLANK(H2), ISBLANK(I2), ISBLANK(J2) ), "", 1.5*SQRT( EXP(2.21*(F2-1)) + EXP(2.21*(G2-1)) + EXP(2.21*(H2-1)) + EXP(2.21*(I2-1)) + EXP(2.21*J2) )/100*2.45 ) -> 0.37356464 | L2: =Agriculture!M47 -> Estimation using 6.7% conversion to NL (https://ec.europa.eu/eurostat/databrowser/bookmark/ad869a47-4196-4282-b054-0a75caf9373f?lang=en)
A3: =Agriculture!A37 -> Agriculture | B3: =Agriculture!C37 -> 2018 | C3: =Agriculture!D37 -> LDPE | D3: =Agriculture!E37 -> 40.723724 | E3: =Agriculture!F37 -> Combined from TNO Sieger Henke and Statistics - APE Europe [WWW Document], n.d. URL https://web.archive.org/web/20230930160250/https://apeeurope.eu/statistics/ (accessed 3.27.24). Using 6.7% conversion to NL | F3: 2 | G3: 1 | H3: 2 | I3: 1 | J3: 2 | K3: =IF( OR( ISBLANK(F3),ISBLANK(G3), ISBLANK(H3), ISBLANK(I3), ISBLANK(J3) ), "", 1.5*SQRT( EXP(2.21*(F3-1)) + EXP(2.21*(G3-1)) + EXP(2.21*(H3-1)) + EXP(2.21*(I3-1)) + EXP(2.21*J3) )/100*2.45 ) -> 0.37356464 | L3: =Agriculture!M37 -> Estimation using 6.7% conversion to NL (https://ec.europa.eu/eurostat/databrowser/bookmark/ad869a47-4196-4282-b054-0a75caf9373f?lang=en)
A4: =Agriculture!A42 -> Agriculture | B4: =Agriculture!C42 -> 2019 | C4: =Agriculture!D42 -> LDPE | D4: =Agriculture!E42 -> 20.034144 | E4: =Agriculture!F42 -> Combined from TNO Sieger Henke and Statistics - APE Europe [WWW Document], n.d. URL https://web.archive.org/web/20230930160250/https://apeeurope.eu/statistics/ (accessed 3.27.24). Using 3.36% conversion to NL | F4: 2 | G4: 1 | H4: 2 | I4: 1 | J4: 2 | K4: =IF( OR( ISBLANK(F4),ISBLANK(G4), ISBLANK(H4), ISBLANK(I4), ISBLANK(J4) ), "", 1.5*SQRT( EXP(2.21*(F4-1)) + EXP(2.21*(G4-1)) + EXP(2.21*(H4-1)) + EXP(2.21*(I4-1)) + EXP(2.21*J4) )/100*2.45 ) -> 0.37356464 | L4: =Agriculture!M42 -> Estimation using 3.36% conversion to NL (Plastics Europe, 2014)
A5: =Agriculture!A32 -> Agriculture | B5: =Agriculture!C32 -> 2018 | C5: =Agriculture!D32 -> LDPE | D5: =Agriculture!E32 -> 19.955032 | E5: =Agriculture!F32 -> Combined from TNO Sieger Henke and Statistics - APE Europe [WWW Document], n.d. URL https://web.archive.org/web/20230930160250/https://apeeurope.eu/statistics/ (accessed 3.27.24). Using 3.36% conversion to NL | F5: 2 | G5: 1 | H5: 2 | I5: 1 | J5: 2 | K5: =IF( OR( ISBLANK(F5),ISBLANK(G5), ISBLANK(H5), ISBLANK(I5), ISBLANK(J5) ), "", 1.5*SQRT( EXP(2.21*(F5-1)) + EXP(2.21*(G5-1)) + EXP(2.21*(H5-1)) + EXP(2.21*(I5-1)) + EXP(2.21*J5) )/100*2.45 ) -> 0.37356464 | L5: =Agriculture!M32 -> Estimation using 3.36% conversion to NL (Plastics Europe, 2014)
A6: =Agriculture!A44 -> Agriculture | B6: =Agriculture!C44 -> 2019 | C6: =Agriculture!D44 -> PVC | D6: =Agriculture!E44 -> 4.7909395 | E6: =Agriculture!F44 -> Combined from TNO Sieger Henke and Statistics - APE Europe [WWW Document], n.d. URL https://web.archive.org/web/20230930160250/https://apeeurope.eu/statistics/ (accessed 3.27.24). Using 6.7% conversion to NL | F6: 2 | G6: 1 | H6: 2 | I6: 1 | J6: 2 | K6: =IF( OR( ISBLANK(F6),ISBLANK(G6), ISBLANK(H6), ISBLANK(I6), ISBLANK(J6) ), "", 1.5*SQRT( EXP(2.21*(F6-1)) + EXP(2.21*(G6-1)) + EXP(2.21*(H6-1)) + EXP(2.21*(I6-1)) + EXP(2.21*J6) )/100*2.45 ) -> 0.37356464 | L6: =Agriculture!M44 -> Estimation using 6.7% conversion to NL (https://ec.europa.eu/eurostat/databrowser/bookmark/ad869a47-4196-4282-b054-0a75caf9373f?lang=en)
A7: =Agriculture!A34 -> Agriculture | B7: =Agriculture!C34 -> 2018 | C7: =Agriculture!D34 -> PVC | D7: =Agriculture!E34 -> 4.7724185 | E7: =Agriculture!F34 -> Combined from TNO Sieger Henke and Statistics - APE Europe [WWW Document], n.d. URL https://web.archive.org/web/20230930160250/https://apeeurope.eu/statistics/ (accessed 3.27.24). Using 6.7% conversion to NL | F7: 2 | G7: 1 | H7: 2 | I7: 1 | J7: 2 | K7: =IF( OR( ISBLANK(F7),ISBLANK(G7), ISBLANK(H7), ISBLANK(I7), ISBLANK(J7) ), "", 1.5*SQRT( EXP(2.21*(F7-1)) + EXP(2.21*(G7-1)) + EXP(2.21*(H7-1)) + EXP(2.21*(I7-1)) + EXP(2.21*J7) )/100*2.45 ) -> 0.37356464 | L7: =Agriculture!M34 -> Estimation using 6.7% conversion to NL (https://ec.europa.eu/eurostat/databrowser/bookmark/ad869a47-4196-4282-b054-0a75caf9373f?lang=en)
A8: =Agriculture!A39 -> Agriculture | B8: =Agriculture!C39 -> 2019 | C8: =Agriculture!D39 -> PVC | D8: =Agriculture!E39 -> 2.3478039 | E8: =Agriculture!F39 -> Combined from TNO Sieger Henke and Statistics - APE Europe [WWW Document], n.d. URL https://web.archive.org/web/20230930160250/https://apeeurope.eu/statistics/ (accessed 3.27.24). Using 3.36% conversion to NL | F8: 2 | G8: 1 | H8: 2 | I8: 1 | J8: 2 | K8: =IF( OR( ISBLANK(F8),ISBLANK(G8), ISBLANK(H8), ISBLANK(I8), ISBLANK(J8) ), "", 1.5*SQRT( EXP(2.21*(F8-1)) + EXP(2.21*(G8-1)) + EXP(2.21*(H8-1)) + EXP(2.21*(I8-1)) + EXP(2.21*J8) )/100*2.45 ) -> 0.37356464 | L8: =Agriculture!M39 -> Estimation using 3.36% conversion to NL (Plastics Europe, 2014)
A9: =Agriculture!A29 -> Agriculture | B9: =Agriculture!C29 -> 2018 | C9: =Agriculture!D29 -> PVC | D9: =Agriculture!E29 -> 2.3385328 | E9: =Agriculture!F29 -> Combined from TNO Sieger Henke and Statistics - APE Europe [WWW Document], n.d. URL https://web.archive.org/web/20230930160250/https://apeeurope.eu/statistics/ (accessed 3.27.24). Using 3.36% conversion to NL | F9: 2 | G9: 1 | H9: 2 | I9: 1 | J9: 2 | K9: =IF( OR( ISBLANK(F9),ISBLANK(G9), ISBLANK(H9), ISBLANK(I9), ISBLANK(J9) ), "", 1.5*SQRT( EXP(2.21*(F9-1)) + EXP(2.21*(G9-1)) + EXP(2.21*(H9-1)) + EXP(2.21*(I9-1)) + EXP(2.21*J9) )/100*2.45 ) -> 0.37356464 | L9: =Agriculture!M29 -> Estimation using 3.36% conversion to NL (Plastics Europe, 2014)
A10: =Agriculture!A48 -> Agriculture | B10: =Agriculture!C48 -> 2019 | C10: =Agriculture!D48 -> HDPE | D10: =Agriculture!E48 -> 0.57869314 | E10: =Agriculture!F48 -> Combined from TNO Sieger Henke and Statistics - APE Europe [WWW Document], n.d. URL https://web.archive.org/web/20230930160250/https://apeeurope.eu/statistics/ (accessed 3.27.24). Using 6.7% conversion to NL | F10: 2 | G10: 1 | H10: 2 | I10: 1 | J10: 2 | K10: =IF( OR( ISBLANK(F10),ISBLANK(G10), ISBLANK(H10), ISBLANK(I10), ISBLANK(J10) ), "", 1.5*SQRT( EXP(2.21*(F10-1)) + EXP(2.21*(G10-1)) + EXP(2.21*(H10-1)) + EXP(2.21*(I10-1)) + EXP(2.21*J10) )/100*2.45 ) -> 0.37356464 | L10: =Agriculture!M48 -> Estimation using 6.7% conversion to NL (https://ec.europa.eu/eurostat/databrowser/bookmark/ad869a47-4196-4282-b054-0a75caf9373f?lang=en)
A11: =Agriculture!A38 -> Agriculture | B11: =Agriculture!C38 -> 2018 | C11: =Agriculture!D38 -> HDPE | D11: =Agriculture!E38 -> 0.576456 | E11: =Agriculture!F38 -> Combined from TNO Sieger Henke and Statistics - APE Europe [WWW Document], n.d. URL https://web.archive.org/web/20230930160250/https://apeeurope.eu/statistics/ (accessed 3.27.24). Using 6.7% conversion to NL | F11: 2 | G11: 1 | H11: 2 | I11: 1 | J11: 2 | K11: =IF( OR( ISBLANK(F11),ISBLANK(G11), ISBLANK(H11), ISBLANK(I11), ISBLANK(J11) ), "", 1.5*SQRT( EXP(2.21*(F11-1)) + EXP(2.21*(G11-1)) + EXP(2.21*(H11-1)) + EXP(2.21*(I11-1)) + EXP(2.21*J11) )/100*2.45 ) -> 0.37356464 | L11: =Agriculture!M38 -> Estimation using 6.7% conversion to NL (https://ec.europa.eu/eurostat/databrowser/bookmark/ad869a47-4196-4282-b054-0a75caf9373f?lang=en)
A12: =Agriculture!A43 -> Agriculture | B12: =Agriculture!C43 -> 2019 | C12: =Agriculture!D43 -> HDPE | D12: =Agriculture!E43 -> 0.28358906 | E12: =Agriculture!F43 -> Combined from TNO Sieger Henke and Statistics - APE Europe [WWW Document], n.d. URL https://web.archive.org/web/20230930160250/https://apeeurope.eu/statistics/ (accessed 3.27.24). Using 3.36% conversion to NL | F12: 2 | G12: 1 | H12: 2 | I12: 1 | J12: 2 | K12: =IF( OR( ISBLANK(F12),ISBLANK(G12), ISBLANK(H12), ISBLANK(I12), ISBLANK(J12) ), "", 1.5*SQRT( EXP(2.21*(F12-1)) + EXP(2.21*(G12-1)) + EXP(2.21*(H12-1)) + EXP(2.21*(I12-1)) + EXP(2.21*J12) )/100*2.45 ) -> 0.37356464 | L12: =Agriculture!M43 -> Estimation using 3.36% conversion to NL (Plastics Europe, 2014)
A13: =Agriculture!A33 -> Agriculture | B13: =Agriculture!C33 -> 2018 | C13: =Agriculture!D33 -> HDPE | D13: =Agriculture!E33 -> 0.2824692 | E13: =Agriculture!F33 -> Combined from TNO Sieger Henke and Statistics - APE Europe [WWW Document], n.d. URL https://web.archive.org/web/20230930160250/https://apeeurope.eu/statistics/ (accessed 3.27.24). Using 3.36% conversion to NL | F13: 2 | G13: 1 | H13: 2 | I13: 1 | J13: 2 | K13: =IF( OR( ISBLANK(F13),ISBLANK(G13), ISBLANK(H13), ISBLANK(I13), ISBLANK(J13) ), "", 1.5*SQRT( EXP(2.21*(F13-1)) + EXP(2.21*(G13-1)) + EXP(2.21*(H13-1)) + EXP(2.21*(I13-1)) + EXP(2.21*J13) )/100*2.45 ) -> 0.37356464 | L13: =Agriculture!M33 -> Estimation using 3.36% conversion to NL (Plastics Europe, 2014)
A14: =Agriculture!A45 -> Agriculture | B14: =Agriculture!C45 -> 2019 | C14: =Agriculture!D45 -> PS | D14: =Agriculture!E45 -> 0.22754023 | E14: =Agriculture!F45 -> Combined from TNO Sieger Henke and Statistics - APE Europe [WWW Document], n.d. URL https://web.archive.org/web/20230930160250/https://apeeurope.eu/statistics/ (accessed 3.27.24). Using 6.7% conversion to NL | F14: 2 | G14: 1 | H14: 2 | I14: 1 | J14: 2 | K14: =IF( OR( ISBLANK(F14),ISBLANK(G14), ISBLANK(H14), ISBLANK(I14), ISBLANK(J14) ), "", 1.5*SQRT( EXP(2.21*(F14-1)) + EXP(2.21*(G14-1)) + EXP(2.21*(H14-1)) + EXP(2.21*(I14-1)) + EXP(2.21*J14) )/100*2.45 ) -> 0.37356464 | L14: =Agriculture!M45 -> Estimation using 6.7% conversion to NL (https://ec.europa.eu/eurostat/databrowser/bookmark/ad869a47-4196-4282-b054-0a75caf9373f?lang=en)
A15: =Agriculture!A46 -> Agriculture | B15: =Agriculture!C46 -> 2019 | C15: =Agriculture!D46 -> PP | D15: =Agriculture!E46 -> 0.22754023 | E15: =Agriculture!F46 -> Combined from TNO Sieger Henke and Statistics - APE Europe [WWW Document], n.d. URL https://web.archive.org/web/20230930160250/https://apeeurope.eu/statistics/ (accessed 3.27.24). Using 6.7% conversion to NL | F15: 2 | G15: 1 | H15: 2 | I15: 1 | J15: 2 | K15: =IF( OR( ISBLANK(F15),ISBLANK(G15), ISBLANK(H15), ISBLANK(I15), ISBLANK(J15) ), "", 1.5*SQRT( EXP(2.21*(F15-1)) + EXP(2.21*(G15-1)) + EXP(2.21*(H15-1)) + EXP(2.21*(I15-1)) + EXP(2.21*J15) )/100*2.45 ) -> 0.37356464 | L15: =Agriculture!M46 -> Estimation using 6.7% conversion to NL (https://ec.europa.eu/eurostat/databrowser/bookmark/ad869a47-4196-4282-b054-0a75caf9373f?lang=en)
A16: =Agriculture!A35 -> Agriculture | B16: =Agriculture!C35 -> 2018 | C16: =Agriculture!D35 -> PS | D16: =Agriculture!E35 -> 0.2266606 | E16: =Agriculture!F35 -> Combined from TNO Sieger Henke and Statistics - APE Europe [WWW Document], n.d. URL https://web.archive.org/web/20230930160250/https://apeeurope.eu/statistics/ (accessed 3.27.24). Using 6.7% conversion to NL | F16: 2 | G16: 1 | H16: 2 | I16: 1 | J16: 2 | K16: =IF( OR( ISBLANK(F16),ISBLANK(G16), ISBLANK(H16), ISBLANK(I16), ISBLANK(J16) ), "", 1.5*SQRT( EXP(2.21*(F16-1)) + EXP(2.21*(G16-1)) + EXP(2.21*(H16-1)) + EXP(2.21*(I16-1)) + EXP(2.21*J16) )/100*2.45 ) -> 0.37356464 | L16: =Agriculture!M35 -> Estimation using 6.7% conversion to NL (https://ec.europa.eu/eurostat/databrowser/bookmark/ad869a47-4196-4282-b054-0a75caf9373f?lang=en)
A17: =Agriculture!A36 -> Agriculture | B17: =Agriculture!C36 -> 2018 | C17: =Agriculture!D36 -> PP | D17: =Agriculture!E36 -> 0.2266606 | E17: =Agriculture!F36 -> Combined from TNO Sieger Henke and Statistics - APE Europe [WWW Document], n.d. URL https://web.archive.org/web/20230930160250/https://apeeurope.eu/statistics/ (accessed 3.27.24). Using 6.7% conversion to NL | F17: 2 | G17: 1 | H17: 2 | I17: 1 | J17: 2 | K17: =IF( OR( ISBLANK(F17),ISBLANK(G17), ISBLANK(H17), ISBLANK(I17), ISBLANK(J17) ), "", 1.5*SQRT( EXP(2.21*(F17-1)) + EXP(2.21*(G17-1)) + EXP(2.21*(H17-1)) + EXP(2.21*(I17-1)) + EXP(2.21*J17) )/100*2.45 ) -> 0.37356464 | L17: =Agriculture!M36 -> Estimation using 6.7% conversion to NL (https://ec.europa.eu/eurostat/databrowser/bookmark/ad869a47-4196-4282-b054-0a75caf9373f?lang=en)
A18: =Agriculture!A40 -> Agriculture | B18: =Agriculture!C40 -> 2019 | C18: =Agriculture!D40 -> PS | D18: =Agriculture!E40 -> 0.11150628 | E18: =Agriculture!F40 -> Combined from TNO Sieger Henke and Statistics - APE Europe [WWW Document], n.d. URL https://web.archive.org/web/20230930160250/https://apeeurope.eu/statistics/ (accessed 3.27.24). Using 3.36% conversion to NL | F18: 2 | G18: 1 | H18: 2 | I18: 1 | J18: 2 | K18: =IF( OR( ISBLANK(F18),ISBLANK(G18), ISBLANK(H18), ISBLANK(I18), ISBLANK(J18) ), "", 1.5*SQRT( EXP(2.21*(F18-1)) + EXP(2.21*(G18-1)) + EXP(2.21*(H18-1)) + EXP(2.21*(I18-1)) + EXP(2.21*J18) )/100*2.45 ) -> 0.37356464 | L18: =Agriculture!M40 -> Estimation using 3.36% conversion to NL (Plastics Europe, 2014)
A19: =Agriculture!A41 -> Agriculture | B19: =Agriculture!C41 -> 2019 | C19: =Agriculture!D41 -> PP | D19: =Agriculture!E41 -> 0.11150628 | E19: =Agriculture!F41 -> Combined from TNO Sieger Henke and Statistics - APE Europe [WWW Document], n.d. URL https://web.archive.org/web/20230930160250/https://apeeurope.eu/statistics/ (accessed 3.27.24). Using 3.36% conversion to NL | F19: 2 | G19: 1 | H19: 2 | I19: 1 | J19: 2 | K19: =IF( OR( ISBLANK(F19),ISBLANK(G19), ISBLANK(H19), ISBLANK(I19), ISBLANK(J19) ), "", 1.5*SQRT( EXP(2.21*(F19-1)) + EXP(2.21*(G19-1)) + EXP(2.21*(H19-1)) + EXP(2.21*(I19-1)) + EXP(2.21*J19) )/100*2.45 ) -> 0.37356464 | L19: =Agriculture!M41 -> Estimation using 3.36% conversion to NL (Plastics Europe, 2014)
A20: =Agriculture!A30 -> Agriculture | B20: =Agriculture!C30 -> 2018 | C20: =Agriculture!D30 -> PS | D20: =Agriculture!E30 -> 0.11106596 | E20: =Agriculture!F30 -> Combined from TNO Sieger Henke and Statistics - APE Europe [WWW Document], n.d. URL https://web.archive.org/web/20230930160250/https://apeeurope.eu/statistics/ (accessed 3.27.24). Using 3.36% conversion to NL | F20: 2 | G20: 1 | H20: 2 | I20: 1 | J20: 2 | K20: =IF( OR( ISBLANK(F20),ISBLANK(G20), ISBLANK(H20), ISBLANK(I20), ISBLANK(J20) ), "", 1.5*SQRT( EXP(2.21*(F20-1)) + EXP(2.21*(G20-1)) + EXP(2.21*(H20-1)) + EXP(2.21*(I20-1)) + EXP(2.21*J20) )/100*2.45 ) -> 0.37356464 | L20: =Agriculture!M30 -> Estimation using 3.36% conversion to NL (Plastics Europe, 2014)
A21: =Agriculture!A31 -> Agriculture | B21: =Agriculture!C31 -> 2018 | C21: =Agriculture!D31 -> PP | D21: =Agriculture!E31 -> 0.11106596 | E21: =Agriculture!F31 -> Combined from TNO Sieger Henke and Statistics - APE Europe [WWW Document], n.d. URL https://web.archive.org/web/20230930160250/https://apeeurope.eu/statistics/ (accessed 3.27.24). Using 3.36% conversion to NL | F21: 2 | G21: 1 | H21: 2 | I21: 1 | J21: 2 | K21: =IF( OR( ISBLANK(F21),ISBLANK(G21), ISBLANK(H21), ISBLANK(I21), ISBLANK(J21) ), "", 1.5*SQRT( EXP(2.21*(F21-1)) + EXP(2.21*(G21-1)) + EXP(2.21*(H21-1)) + EXP(2.21*(I21-1)) + EXP(2.21*J21) )/100*2.45 ) -> 0.37356464 | L21: =Agriculture!M31 -> Estimation using 3.36% conversion to NL (Plastics Europe, 2014)
A22: Clothing (product sector) | B22: 2019 | C22: PET | D22: 22.7689 | E22: Information combined from: CBS (2019) and Synthetic Fibers (polymerdatabase.com) | F22: 1 | G22: 1 | H22: 2 | I22: 3 | J22: 2 | K22: =IF( OR( ISBLANK(F22),ISBLANK(G22), ISBLANK(H22), ISBLANK(I22), ISBLANK(J22) ), "", 1.5*SQRT( EXP(2.21*(F22-1)) + EXP(2.21*(G22-1)) + EXP(2.21*(H22-1)) + EXP(2.21*(I22-1)) + EXP(2.21*J22) )/100*2.45 ) -> 0.48935256
A23: Clothing (product sector) | B23: 2019 | C23: PA | D23: 3.5484 | E23: Information combined from: CBS (2019) and Synthetic Fibers (polymerdatabase.com) | F23: 1 | G23: 1 | H23: 2 | I23: 3 | J23: 2 | K23: =IF( OR( ISBLANK(F23),ISBLANK(G23), ISBLANK(H23), ISBLANK(I23), ISBLANK(J23) ), "", 1.5*SQRT( EXP(2.21*(F23-1)) + EXP(2.21*(G23-1)) + EXP(2.21*(H23-1)) + EXP(2.21*(I23-1)) + EXP(2.21*J23) )/100*2.45 ) -> 0.48935256
A24: Clothing (product sector) | B24: 2019 | C24: Acryl | D24: 2.6613 | E24: Information combined from: CBS (2019) and Synthetic Fibers (polymerdatabase.com) | F24: 1 | G24: 1 | H24: 2 | I24: 3 | J24: 2 | K24: =IF( OR( ISBLANK(F24),ISBLANK(G24), ISBLANK(H24), ISBLANK(I24), ISBLANK(J24) ), "", 1.5*SQRT( EXP(2.21*(F24-1)) + EXP(2.21*(G24-1)) + EXP(2.21*(H24-1)) + EXP(2.21*(I24-1)) + EXP(2.21*J24) )/100*2.45 ) -> 0.48935256
A25: Clothing (product sector) | B25: 2019 | C25: HDPE | D25: 0.2957 | E25: Information combined from: CBS (2019) and Synthetic Fibers (polymerdatabase.com) | F25: 1 | G25: 1 | H25: 2 | I25: 3 | J25: 2 | K25: =IF( OR( ISBLANK(F25),ISBLANK(G25), ISBLANK(H25), ISBLANK(I25), ISBLANK(J25) ), "", 1.5*SQRT( EXP(2.21*(F25-1)) + EXP(2.21*(G25-1)) + EXP(2.21*(H25-1)) + EXP(2.21*(I25-1)) + EXP(2.21*J25) )/100*2.45 ) -> 0.48935256
A26: Clothing (product sector) | B26: 2019 | C26: PP | D26: 0.2957 | E26: Information combined from: CBS (2019) and Synthetic Fibers (polymerdatabase.com) | F26: 1 | G26: 1 | H26: 2 | I26: 3 | J26: 2 | K26: =IF( OR( ISBLANK(F26),ISBLANK(G26), ISBLANK(H26), ISBLANK(I26), ISBLANK(J26) ), "", 1.5*SQRT( EXP(2.21*(F26-1)) + EXP(2.21*(G26-1)) + EXP(2.21*(H26-1)) + EXP(2.21*(I26-1)) + EXP(2.21*J26) )/100*2.45 ) -> 0.48935256
A27: Domestic primary plastic production | B27: 1995 | C27: LDPE | D27: 1435 | E27: Statistics | Eurostat [WWW Document], n.d. URL https://ec.europa.eu/eurostat/databrowser/view/DS-056120__custom_5851448/default/table (accessed 2.15.24). | F27: 1 | G27: 1 | H27: 1 | I27: 2 | J27: 2 | K27: =IF( OR( ISBLANK(F27),ISBLANK(G27), ISBLANK(H27), ISBLANK(I27), ISBLANK(J27) ), "", 1.5*SQRT( EXP(2.21*(F27-1)) + EXP(2.21*(G27-1)) + EXP(2.21*(H27-1)) + EXP(2.21*(I27-1)) + EXP(2.21*J27) )/100*2.45 ) -> 0.35859414 | L27: See 'Pellets_trade' document and pellet_input.py in the Microsoft Teams folder 'Pellet'
A28: Domestic primary plastic production | B28: 1995 | C28: HDPE | D28: 290 | E28: Statistics | Eurostat [WWW Document], n.d. URL https://ec.europa.eu/eurostat/databrowser/view/DS-056120__custom_5851448/default/table (accessed 2.15.24). | F28: 1 | G28: 1 | H28: 1 | I28: 2 | J28: 2 | K28: =IF( OR( ISBLANK(F28),ISBLANK(G28), ISBLANK(H28), ISBLANK(I28), ISBLANK(J28) ), "", 1.5*SQRT( EXP(2.21*(F28-1)) + EXP(2.21*(G28-1)) + EXP(2.21*(H28-1)) + EXP(2.21*(I28-1)) + EXP(2.21*J28) )/100*2.45 ) -> 0.35859414 | L28: See 'Pellets_trade' document and pellet_input.py in the Microsoft Teams folder 'Pellet'
A29: Domestic primary plastic production | B29: 1995 | C29: PP | D29: 852 | E29: Statistics | Eurostat [WWW Document], n.d. URL https://ec.europa.eu/eurostat/databrowser/view/DS-056120__custom_5851448/default/table (accessed 2.15.24). | F29: 1 | G29: 1 | H29: 1 | I29: 2 | J29: 2 | K29: =IF( OR( ISBLANK(F29),ISBLANK(G29), ISBLANK(H29), ISBLANK(I29), ISBLANK(J29) ), "", 1.5*SQRT( EXP(2.21*(F29-1)) + EXP(2.21*(G29-1)) + EXP(2.21*(H29-1)) + EXP(2.21*(I29-1)) + EXP(2.21*J29) )/100*2.45 ) -> 0.35859414 | L29: See 'Pellets_trade' document and pellet_input.py in the Microsoft Teams folder 'Pellet'
A30: Domestic primary plastic production | B30: 1995 | C30: PS | D30: 4 | E30: Statistics | Eurostat [WWW Document], n.d. URL https://ec.europa.eu/eurostat/databrowser/view/DS-056120__custom_5851448/default/table (accessed 2.15.24). | F30: 1 | G30: 1 | H30: 1 | I30: 2 | J30: 2 | K30: =IF( OR( ISBLANK(F30),ISBLANK(G30), ISBLANK(H30), ISBLANK(I30), ISBLANK(J30) ), "", 1.5*SQRT( EXP(2.21*(F30-1)) + EXP(2.21*(G30-1)) + EXP(2.21*(H30-1)) + EXP(2.21*(I30-1)) + EXP(2.21*J30) )/100*2.45 ) -> 0.35859414 | L30: See 'Pellets_trade' document and pellet_input.py in the Microsoft Teams folder 'Pellet'
A31: Domestic primary plastic production | B31: 1995 | C31: EPS | D31: 191 | E31: Statistics | Eurostat [WWW Document], n.d. URL https://ec.europa.eu/eurostat/databrowser/view/DS-056120__custom_5851448/default/table (accessed 2.15.24). | F31: 1 | G31: 1 | H31: 1 | I31: 2 | J31: 2 | K31: =IF( OR( ISBLANK(F31),ISBLANK(G31), ISBLANK(H31), ISBLANK(I31), ISBLANK(J31) ), "", 1.5*SQRT( EXP(2.21*(F31-1)) + EXP(2.21*(G31-1)) + EXP(2.21*(H31-1)) + EXP(2.21*(I31-1)) + EXP(2.21*J31) )/100*2.45 ) -> 0.35859414 | L31: See 'Pellets_trade' document and pellet_input.py in the Microsoft Teams folder 'Pellet'
A32: Domestic primary plastic production | B32: 1995 | C32: PVC | D32: 610 | E32: Statistics | Eurostat [WWW Document], n.d. URL https://ec.europa.eu/eurostat/databrowser/view/DS-056120__custom_5851448/default/table (accessed 2.15.24). | F32: 1 | G32: 1 | H32: 1 | I32: 2 | J32: 2 | K32: =IF( OR( ISBLANK(F32),ISBLANK(G32), ISBLANK(H32), ISBLANK(I32), ISBLANK(J32) ), "", 1.5*SQRT( EXP(2.21*(F32-1)) + EXP(2.21*(G32-1)) + EXP(2.21*(H32-1)) + EXP(2.21*(I32-1)) + EXP(2.21*J32) )/100*2.45 ) -> 0.35859414 | L32: See 'Pellets_trade' document and pellet_input.py in the Microsoft Teams folder 'Pellet'
A33: Domestic primary plastic production | B33: 1995 | C33: PET | D33: 0 | E33: Statistics | Eurostat [WWW Document], n.d. URL https://ec.europa.eu/eurostat/databrowser/view/DS-056120__custom_5851448/default/table (accessed 2.15.24). | F33: 1 | G33: 1 | H33: 1 | I33: 2 | J33: 2 | K33: =IF( OR( ISBLANK(F33),ISBLANK(G33), ISBLANK(H33), ISBLANK(I33), ISBLANK(J33) ), "", 1.5*SQRT( EXP(2.21*(F33-1)) + EXP(2.21*(G33-1)) + EXP(2.21*(H33-1)) + EXP(2.21*(I33-1)) + EXP(2.21*J33) )/100*2.45 ) -> 0.35859414 | L33: See 'Pellets_trade' document and pellet_input.py in the Microsoft Teams folder 'Pellet'
A34: Domestic primary plastic production | B34: 1995 | C34: ABS | D34: 144 | E34: Statistics | Eurostat [WWW Document], n.d. URL https://ec.europa.eu/eurostat/databrowser/view/DS-056120__custom_5851448/default/table (accessed 2.15.24). | F34: 1 | G34: 1 | H34: 1 | I34: 2 | J34: 2 | K34: =IF( OR( ISBLANK(F34),ISBLANK(G34), ISBLANK(H34), ISBLANK(I34), ISBLANK(J34) ), "", 1.5*SQRT( EXP(2.21*(F34-1)) + EXP(2.21*(G34-1)) + EXP(2.21*(H34-1)) + EXP(2.21*(I34-1)) + EXP(2.21*J34) )/100*2.45 ) -> 0.35859414 | L34: See 'Pellets_trade' document and pellet_input.py in the Microsoft Teams folder 'Pellet'
A35: Domestic primary plastic production | B35: 1995 | C35: PC | D35: 337 | E35: Statistics | Eurostat [WWW Document], n.d. URL https://ec.europa.eu/eurostat/databrowser/view/DS-056120__custom_5851448/default/table (accessed 2.15.24). | F35: 1 | G35: 1 | H35: 1 | I35: 2 | J35: 2 | K35: =IF( OR( ISBLANK(F35),ISBLANK(G35), ISBLANK(H35), ISBLANK(I35), ISBLANK(J35) ), "", 1.5*SQRT( EXP(2.21*(F35-1)) + EXP(2.21*(G35-1)) + EXP(2.21*(H35-1)) + EXP(2.21*(I35-1)) + EXP(2.21*J35) )/100*2.45 ) -> 0.35859414 | L35: See 'Pellets_trade' document and pellet_input.py in the Microsoft Teams folder 'Pellet'
A36: Domestic primary plastic production | B36: 1995 | C36: PMMA | D36: 233 | E36: Statistics | Eurostat [WWW Document], n.d. URL https://ec.europa.eu/eurostat/databrowser/view/DS-056120__custom_5851448/default/table (accessed 2.15.24). | F36: 1 | G36: 1 | H36: 1 | I36: 2 | J36: 2 | K36: =IF( OR( ISBLANK(F36),ISBLANK(G36), ISBLANK(H36), ISBLANK(I36), ISBLANK(J36) ), "", 1.5*SQRT( EXP(2.21*(F36-1)) + EXP(2.21*(G36-1)) + EXP(2.21*(H36-1)) + EXP(2.21*(I36-1)) + EXP(2.21*J36) )/100*2.45 ) -> 0.35859414 | L36: See 'Pellets_trade' document and pellet_input.py in the Microsoft Teams folder 'Pellet'
A37: Domestic primary plastic production | B37: 1995 | C37: PA | D37: 200 | E37: Statistics | Eurostat [WWW Document], n.d. URL https://ec.europa.eu/eurostat/databrowser/view/DS-056120__custom_5851448/default/table (accessed 2.15.24). | F37: 1 | G37: 1 | H37: 1 | I37: 2 | J37: 2 | K37: =IF( OR( ISBLANK(F37),ISBLANK(G37), ISBLANK(H37), ISBLANK(I37), ISBLANK(J37) ), "", 1.5*SQRT( EXP(2.21*(F37-1)) + EXP(2.21*(G37-1)) + EXP(2.21*(H37-1)) + EXP(2.21*(I37-1)) + EXP(2.21*J37) )/100*2.45 ) -> 0.35859414 | L37: See 'Pellets_trade' document and pellet_input.py in the Microsoft Teams folder 'Pellet'
A38: Domestic primary plastic production | B38: 1995 | C38: PUR | D38: 98 | E38: Statistics | Eurostat [WWW Document], n.d. URL https://ec.europa.eu/eurostat/databrowser/view/DS-056120__custom_5851448/default/table (accessed 2.15.24). | F38: 1 | G38: 1 | H38: 1 | I38: 2 | J38: 2 | K38: =IF( OR( ISBLANK(F38),ISBLANK(G38), ISBLANK(H38), ISBLANK(I38), ISBLANK(J38) ), "", 1.5*SQRT( EXP(2.21*(F38-1)) + EXP(2.21*(G38-1)) + EXP(2.21*(H38-1)) + EXP(2.21*(I38-1)) + EXP(2.21*J38) )/100*2.45 ) -> 0.35859414 | L38: See 'Pellets_trade' document and pellet_input.py in the Microsoft Teams folder 'Pellet'
... A377: Domestic primary plastic production | B377: 2021 | C377: OTHER | D377: 2480 | E377: Statistics | Eurostat [WWW Document], n.d. URL https://ec.europa.eu/eurostat/databrowser/view/DS-056120__custom_5851448/default/table (accessed 2.15.24). | F377: 1 | G377: 1 | H377: 1 | I377: 2 | J377: 2 | K377: =IF( OR( ISBLANK(F377),ISBLANK(G377), ISBLANK(H377), ISBLANK(I377), ISBLANK(J377) ), "", 1.5*SQRT( EXP(2.21*(F377-1)) + EXP(2.21*(G377-1)) + EXP(2.21*(H377-1)) + EXP(2.21*(I377-1)) + EXP(2.21*J377) )/100*2.45 ) -> 0.35859414 | L377: See 'Pellets_trade' document and pellet_input.py in the Microsoft Teams folder 'Pellet'
A378: Household textiles (product sector) | B378: 2017 | C378: PET | D378: 30.108567 | E378: Information combined from: CBS (2019), Synthetic Fibers (polymerdatabase.com), and Kawecki & Nowack (2019) | F378: 1 | G378: 1 | H378: 2 | I378: 3 | J378: 2 | K378: =IF( OR( ISBLANK(F378),ISBLANK(G378), ISBLANK(H378), ISBLANK(I378), ISBLANK(J378) ), "", 1.5*SQRT( EXP(2.21*(F378-1)) + EXP(2.21*(G378-1)) + EXP(2.21*(H378-1)) + EXP(2.21*(I378-1)) + EXP(2.21*J378) )/100*2.45 ) -> 0.48935256
...

Sheet Input_EU
A1: Compartment | B1: Year | C1: Material | D1: Data (kt) | E1: Source | F1: Geo | G1: Temp | H1: Mat | I1: Tech | J1: Rel | K1: Spread | L1: Comments
A2: =Agriculture!A10 -> Agriculture | B2: =Agriculture!C10 -> 2018 | C2: =Agriculture!D10 -> PS | D2: =Agriculture!E10 -> 3.9507479 | E2: =Agriculture!F10 -> Combined from TNO Sieger Henke and Statistics - APE Europe [WWW Document], n.d. URL https://web.archive.org/web/20230930160250/https://apeeurope.eu/statistics/ (accessed 3.27.24). | F2: 1 | G2: 2 | H2: 2 | I2: 1 | J2: 2 | K2: =IF( OR( ISBLANK(F2),ISBLANK(G2), ISBLANK(H2), ISBLANK(I2), ISBLANK(J2) ), "", 1.5*SQRT( EXP(2.21*(F2-1)) + EXP(2.21*(G2-1)) + EXP(2.21*(H2-1)) + EXP(2.21*(I2-1)) + EXP(2.21*J2) )/100*2.45 ) -> 0.37356464
A3: =Agriculture!A11 -> Agriculture | B3: =Agriculture!C11 -> 2018 | C3: =Agriculture!D11 -> PP | D3: =Agriculture!E11 -> 3.9660876 | E3: =Agriculture!F11 -> Combined from TNO Sieger Henke and Statistics - APE Europe [WWW Document], n.d. URL https://web.archive.org/web/20230930160250/https://apeeurope.eu/statistics/ (accessed 3.27.24). | F3: 1 | G3: 2 | H3: 2 | I3: 1 | J3: 2 | K3: =IF( OR( ISBLANK(F3),ISBLANK(G3), ISBLANK(H3), ISBLANK(I3), ISBLANK(J3) ), "", 1.5*SQRT( EXP(2.21*(F3-1)) + EXP(2.21*(G3-1)) + EXP(2.21*(H3-1)) + EXP(2.21*(I3-1)) + EXP(2.21*J3) )/100*2.45 ) -> 0.37356464
A4: =Agriculture!A15 -> Agriculture | B4: =Agriculture!C15 -> 2019 | C4: =Agriculture!D15 -> PS | D4: =Agriculture!E15 -> 3.9660876 | E4: =Agriculture!F15 -> Combined from TNO Sieger Henke and Statistics - APE Europe [WWW Document], n.d. URL https://web.archive.org/web/20230930160250/https://apeeurope.eu/statistics/ (accessed 3.27.24). | F4: 1 | G4: 2 | H4: 2 | I4: 1 | J4: 2 | K4: =IF( OR( ISBLANK(F4),ISBLANK(G4), ISBLANK(H4), ISBLANK(I4), ISBLANK(J4) ), "", 1.5*SQRT( EXP(2.21*(F4-1)) + EXP(2.21*(G4-1)) + EXP(2.21*(H4-1)) + EXP(2.21*(I4-1)) + EXP(2.21*J4) )/100*2.45 ) -> 0.37356464
A5: =Agriculture!A16 -> Agriculture | B5: =Agriculture!C16 -> 2019 | C5: =Agriculture!D16 -> PP | D5: =Agriculture!E16 -> 3.9660876 | E5: =Agriculture!F16 -> Combined from TNO Sieger Henke and Statistics - APE Europe [WWW Document], n.d. URL https://web.archive.org/web/20230930160250/https://apeeurope.eu/statistics/ (accessed 3.27.24). | F5: 1 | G5: 2 | H5: 2 | I5: 1 | J5: 2 | K5: =IF( OR( ISBLANK(F5),ISBLANK(G5), ISBLANK(H5), ISBLANK(I5), ISBLANK(J5) ), "", 1.5*SQRT( EXP(2.21*(F5-1)) + EXP(2.21*(G5-1)) + EXP(2.21*(H5-1)) + EXP(2.21*(I5-1)) + EXP(2.21*J5) )/100*2.45 ) -> 0.37356464
A6: =Agriculture!A13 -> Agriculture | B6: =Agriculture!C13 -> 2018 | C6: =Agriculture!D13 -> HDPE | D6: =Agriculture!E13 -> 5.6494845 | E6: =Agriculture!F13 -> Combined from TNO Sieger Henke and Statistics - APE Europe [WWW Document], n.d. URL https://web.archive.org/web/20230930160250/https://apeeurope.eu/statistics/ (accessed 3.27.24). | F6: 1 | G6: 2 | H6: 2 | I6: 1 | J6: 2 | K6: =IF( OR( ISBLANK(F6),ISBLANK(G6), ISBLANK(H6), ISBLANK(I6), ISBLANK(J6) ), "", 1.5*SQRT( EXP(2.21*(F6-1)) + EXP(2.21*(G6-1)) + EXP(2.21*(H6-1)) + EXP(2.21*(I6-1)) + EXP(2.21*J6) )/100*2.45 ) -> 0.37356464
A7: =Agriculture!A18 -> Agriculture | B7: =Agriculture!C18 -> 2019 | C7: =Agriculture!D18 -> HDPE | D7: =Agriculture!E18 -> 5.67142 | E7: =Agriculture!F18 -> Combined from TNO Sieger Henke and Statistics - APE Europe [WWW Document], n.d. URL https://web.archive.org/web/20230930160250/https://apeeurope.eu/statistics/ (accessed 3.27.24). | F7: 1 | G7: 2 | H7: 2 | I7: 1 | J7: 2 | K7: =IF( OR( ISBLANK(F7),ISBLANK(G7), ISBLANK(H7), ISBLANK(I7), ISBLANK(J7) ), "", 1.5*SQRT( EXP(2.21*(F7-1)) + EXP(2.21*(G7-1)) + EXP(2.21*(H7-1)) + EXP(2.21*(I7-1)) + EXP(2.21*J7) )/100*2.45 ) -> 0.37356464
A8: =Agriculture!A9 -> Agriculture | B8: =Agriculture!C9 -> 2018 | C8: =Agriculture!D9 -> PVC | D8: =Agriculture!E9 -> 56.385015 | E8: =Agriculture!F9 -> Combined from TNO Sieger Henke and Statistics - APE Europe [WWW Document], n.d. URL https://web.archive.org/web/20230930160250/https://apeeurope.eu/statistics/ (accessed 3.27.24). | F8: 1 | G8: 2 | H8: 2 | I8: 1 | J8: 2 | K8: =IF( OR( ISBLANK(F8),ISBLANK(G8), ISBLANK(H8), ISBLANK(I8), ISBLANK(J8) ), "", 1.5*SQRT( EXP(2.21*(F8-1)) + EXP(2.21*(G8-1)) + EXP(2.21*(H8-1)) + EXP(2.21*(I8-1)) + EXP(2.21*J8) )/100*2.45 ) -> 0.37356464
A9: =Agriculture!A14 -> Agriculture | B9: =Agriculture!C14 -> 2019 | C9: =Agriculture!D14 -> PVC | D9: =Agriculture!E14 -> 56.603943 | E9: =Agriculture!F14 -> Combined from TNO Sieger Henke and Statistics - APE Europe [WWW Document], n.d. URL https://web.archive.org/web/20230930160250/https://apeeurope.eu/statistics/ (accessed 3.27.24). | F9: 1 | G9: 2 | H9: 2 | I9: 1 | J9: 2 | K9: =IF( OR( ISBLANK(F9),ISBLANK(G9), ISBLANK(H9), ISBLANK(I9), ISBLANK(J9) ), "", 1.5*SQRT( EXP(2.21*(F9-1)) + EXP(2.21*(G9-1)) + EXP(2.21*(H9-1)) + EXP(2.21*(I9-1)) + EXP(2.21*J9) )/100*2.45 ) -> 0.37356464
A10: =Agriculture!A12 -> Agriculture | B10: =Agriculture!C12 -> 2018 | C10: =Agriculture!D12 -> LDPE | D10: =Agriculture!E12 -> 622.871 | E10: =Agriculture!F12 -> Combined from TNO Sieger Henke and Statistics - APE Europe [WWW Document], n.d. URL https://web.archive.org/web/20230930160250/https://apeeurope.eu/statistics/ (accessed 3.27.24). | F10: 1 | G10: 2 | H10: 2 | I10: 1 | J10: 2 | K10: =IF( OR( ISBLANK(F10),ISBLANK(G10), ISBLANK(H10), ISBLANK(I10), ISBLANK(J10) ), "", 1.5*SQRT( EXP(2.21*(F10-1)) + EXP(2.21*(G10-1)) + EXP(2.21*(H10-1)) + EXP(2.21*(I10-1)) + EXP(2.21*J10) )/100*2.45 ) -> 0.37356464
A11: =Agriculture!A17 -> Agriculture | B11: =Agriculture!C17 -> 2019 | C11: =Agriculture!D17 -> LDPE | D11: =Agriculture!E17 -> 625.28945 | E11: =Agriculture!F17 -> Combined from TNO Sieger Henke and Statistics - APE Europe [WWW Document], n.d. URL https://web.archive.org/web/20230930160250/https://apeeurope.eu/statistics/ (accessed 3.27.24). | F11: 1 | G11: 2 | H11: 2 | I11: 1 | J11: 2 | K11: =IF( OR( ISBLANK(F11),ISBLANK(G11), ISBLANK(H11), ISBLANK(I11), ISBLANK(J11) ), "", 1.5*SQRT( EXP(2.21*(F11-1)) + EXP(2.21*(G11-1)) + EXP(2.21*(H11-1)) + EXP(2.21*(I11-1)) + EXP(2.21*J11) )/100*2.45 ) -> 0.37356464
A12: Clothing (product sector) | B12: 2017 | C12: LDPE | D12: 0 | E12: Textiles in Europe's circular economy — European Environment Agency (europa.eu) | F12: 1 | G12: 1 | H12: 3 | I12: 1 | J12: 2 | K12: =IF( OR( ISBLANK(F12),ISBLANK(G12), ISBLANK(H12), ISBLANK(I12), ISBLANK(J12) ), "", 1.5*SQRT( EXP(2.21*(F12-1)) + EXP(2.21*(G12-1)) + EXP(2.21*(H12-1)) + EXP(2.21*(I12-1)) + EXP(2.21*J12) )/100*2.45 ) -> 0.47802211 | L12: Calculated based on the total EU textile consumption (8351.04 kt) and the fractions for the different compartments at NL scale (see table above).
A13: Clothing (product sector) | B13: 2017 | C13: HDPE | D13: 6.0673285 | E13: Textiles in Europe's circular economy — European Environment Agency (europa.eu) | F13: 1 | G13: 1 | H13: 3 | I13: 1 | J13: 2 | K13: =IF( OR( ISBLANK(F13),ISBLANK(G13), ISBLANK(H13), ISBLANK(I13), ISBLANK(J13) ), "", 1.5*SQRT( EXP(2.21*(F13-1)) + EXP(2.21*(G13-1)) + EXP(2.21*(H13-1)) + EXP(2.21*(I13-1)) + EXP(2.21*J13) )/100*2.45 ) -> 0.47802211 | L13: Calculated based on the total EU textile consumption (8351.04 kt) and the fractions for the different compartments at NL scale (see table above).
A14: Clothing (product sector) | B14: 2017 | C14: PP | D14: 6.0673285 | E14: Textiles in Europe's circular economy — European Environment Agency (europa.eu) | F14: 1 | G14: 1 | H14: 3 | I14: 1 | J14: 2 | K14: =IF( OR( ISBLANK(F14),ISBLANK(G14), ISBLANK(H14), ISBLANK(I14), ISBLANK(J14) ), "", 1.5*SQRT( EXP(2.21*(F14-1)) + EXP(2.21*(G14-1)) + EXP(2.21*(H14-1)) + EXP(2.21*(I14-1)) + EXP(2.21*J14) )/100*2.45 ) -> 0.47802211 | L14: Calculated based on the total EU textile consumption (8351.04 kt) and the fractions for the different compartments at NL scale (see table above).
A15: Clothing (product sector) | B15: 2017 | C15: PS | D15: 0 | E15: Textiles in Europe's circular economy — European Environment Agency (europa.eu) | F15: 1 | G15: 1 | H15: 3 | I15: 1 | J15: 2 | K15: =IF( OR( ISBLANK(F15),ISBLANK(G15), ISBLANK(H15), ISBLANK(I15), ISBLANK(J15) ), "", 1.5*SQRT( EXP(2.21*(F15-1)) + EXP(2.21*(G15-1)) + EXP(2.21*(H15-1)) + EXP(2.21*(I15-1)) + EXP(2.21*J15) )/100*2.45 ) -> 0.47802211 | L15: Calculated based on the total EU textile consumption (8351.04 kt) and the fractions for the different compartments at NL scale (see table above).
A16: Clothing (product sector) | B16: 2017 | C16: EPS | D16: 0 | E16: Textiles in Europe's circular economy — European Environment Agency (europa.eu) | F16: 1 | G16: 1 | H16: 3 | I16: 1 | J16: 2 | K16: =IF( OR( ISBLANK(F16),ISBLANK(G16), ISBLANK(H16), ISBLANK(I16), ISBLANK(J16) ), "", 1.5*SQRT( EXP(2.21*(F16-1)) + EXP(2.21*(G16-1)) + EXP(2.21*(H16-1)) + EXP(2.21*(I16-1)) + EXP(2.21*J16) )/100*2.45 ) -> 0.47802211 | L16: Calculated based on the total EU textile consumption (8351.04 kt) and the fractions for the different compartments at NL scale (see table above).
A17: Clothing (product sector) | B17: 2017 | C17: PVC | D17: 0 | E17: Textiles in Europe's circular economy — European Environment Agency (europa.eu) | F17: 1 | G17: 1 | H17: 3 | I17: 1 | J17: 2 | K17: =IF( OR( ISBLANK(F17),ISBLANK(G17), ISBLANK(H17), ISBLANK(I17), ISBLANK(J17) ), "", 1.5*SQRT( EXP(2.21*(F17-1)) + EXP(2.21*(G17-1)) + EXP(2.21*(H17-1)) + EXP(2.21*(I17-1)) + EXP(2.21*J17) )/100*2.45 ) -> 0.47802211 | L17: Calculated based on the total EU textile consumption (8351.04 kt) and the fractions for the different compartments at NL scale (see table above).
A18: Clothing (product sector) | B18: 2017 | C18: PET | D18: 467.1843 | E18: Textiles in Europe's circular economy — European Environment Agency (europa.eu) | F18: 1 | G18: 1 | H18: 3 | I18: 1 | J18: 2 | K18: =IF( OR( ISBLANK(F18),ISBLANK(G18), ISBLANK(H18), ISBLANK(I18), ISBLANK(J18) ), "", 1.5*SQRT( EXP(2.21*(F18-1)) + EXP(2.21*(G18-1)) + EXP(2.21*(H18-1)) + EXP(2.21*(I18-1)) + EXP(2.21*J18) )/100*2.45 ) -> 0.47802211 | L18: Calculated based on the total EU textile consumption (8351.04 kt) and the fractions for the different compartments at NL scale (see table above).
A19: Clothing (product sector) | B19: 2017 | C19: PA | D19: 72.807942 | E19: Textiles in Europe's circular economy — European Environment Agency (europa.eu) | F19: 1 | G19: 1 | H19: 3 | I19: 1 | J19: 2 | K19: =IF( OR( ISBLANK(F19),ISBLANK(G19), ISBLANK(H19), ISBLANK(I19), ISBLANK(J19) ), "", 1.5*SQRT( EXP(2.21*(F19-1)) + EXP(2.21*(G19-1)) + EXP(2.21*(H19-1)) + EXP(2.21*(I19-1)) + EXP(2.21*J19) )/100*2.45 ) -> 0.47802211 | L19: Calculated based on the total EU textile consumption (8351.04 kt) and the fractions for the different compartments at NL scale (see table above).
A20: Clothing (product sector) | B20: 2017 | C20: Acryl | D20: 54.605957 | E20: Textiles in Europe's circular economy — European Environment Agency (europa.eu) | F20: 1 | G20: 1 | H20: 3 | I20: 1 | J20: 2 | K20: =IF( OR( ISBLANK(F20),ISBLANK(G20), ISBLANK(H20), ISBLANK(I20), ISBLANK(J20) ), "", 1.5*SQRT( EXP(2.21*(F20-1)) + EXP(2.21*(G20-1)) + EXP(2.21*(H20-1)) + EXP(2.21*(I20-1)) + EXP(2.21*J20) )/100*2.45 ) -> 0.47802211 | L20: Calculated based on the total EU textile consumption (8351.04 kt) and the fractions for the different compartments at NL scale (see table above).
A21: Domestic primary plastic production | B21: 2015 | C21: ABS | D21: 400 | E21: Statistics | Eurostat [WWW Document], n.d. URL https://ec.europa.eu/eurostat/databrowser/view/DS-056120__custom_6262207/default/table (accessed 2.15.24). | F21: 1 | G21: 1 | H21: 1 | I21: 2 | J21: 2 | K21: =IF( OR( ISBLANK(F21),ISBLANK(G21), ISBLANK(H21), ISBLANK(I21), ISBLANK(J21) ), "", 1.5*SQRT( EXP(2.21*(F21-1)) + EXP(2.21*(G21-1)) + EXP(2.21*(H21-1)) + EXP(2.21*(I21-1)) + EXP(2.21*J21) )/100*2.45 ) -> 0.35859414 | L21: See 'Pellets_trade' document and pellet_input.py in the Microsoft Teams folder 'Pellet'
A22: Domestic primary plastic production | B22: 2013 | C22: ABS | D22: 468 | E22: Statistics | Eurostat [WWW Document], n.d. URL https://ec.europa.eu/eurostat/databrowser/view/DS-056120__custom_6262207/default/table (accessed 2.15.24). | F22: 1 | G22: 1 | H22: 1 | I22: 2 | J22: 2 | K22: =IF( OR( ISBLANK(F22),ISBLANK(G22), ISBLANK(H22), ISBLANK(I22), ISBLANK(J22) ), "", 1.5*SQRT( EXP(2.21*(F22-1)) + EXP(2.21*(G22-1)) + EXP(2.21*(H22-1)) + EXP(2.21*(I22-1)) + EXP(2.21*J22) )/100*2.45 ) -> 0.35859414 | L22: See 'Pellets_trade' document and pellet_input.py in the Microsoft Teams folder 'Pellet'
A23: Domestic primary plastic production | B23: 2016 | C23: ABS | D23: 551 | E23: Statistics | Eurostat [WWW Document], n.d. URL https://ec.europa.eu/eurostat/databrowser/view/DS-056120__custom_6262207/default/table (accessed 2.15.24). | F23: 1 | G23: 1 | H23: 1 | I23: 2 | J23: 2 | K23: =IF( OR( ISBLANK(F23),ISBLANK(G23), ISBLANK(H23), ISBLANK(I23), ISBLANK(J23) ), "", 1.5*SQRT( EXP(2.21*(F23-1)) + EXP(2.21*(G23-1)) + EXP(2.21*(H23-1)) + EXP(2.21*(I23-1)) + EXP(2.21*J23) )/100*2.45 ) -> 0.35859414 | L23: See 'Pellets_trade' document and pellet_input.py in the Microsoft Teams folder 'Pellet'
... A523: Import of primary plastics | B523: 2021 | C523: OTHER | D523: 1687 | E523: Statistics | Eurostat [WWW Document], n.d. URL https://ec.europa.eu/eurostat/databrowser/view/DS-056120__custom_6262207/default/table (accessed 2.15.24). | F523: 1 | G523: 1 | H523: 1 | I523: 2 | J523: 2 | K523: =IF( OR( ISBLANK(F523),ISBLANK(G523), ISBLANK(H523), ISBLANK(I523), ISBLANK(J523) ), "", 1.5*SQRT( EXP(2.21*(F523-1)) + EXP(2.21*(G523-1)) + EXP(2.21*(H523-1)) + EXP(2.21*(I523-1)) + EXP(2.21*J523) )/100*2.45 ) -> 0.35859414 | L523: See 'Pellets_trade' document and pellet_input.py in the Microsoft Teams folder 'Pellet'
A524: Intentionally produced microparticles | B524: 2020 | C524: PS | D524: =Intentionally_produced_MPs!G57 -> 0 | E524: Information combined from: Scudo et al. (2017), Microplastics Annex XV Report (2020), and Statistics | Eurostat | F524: 1 | G524: 1 | H524: 3 | I524: 1 | J524: 1 | K524: =IF( OR( ISBLANK(F524),ISBLANK(G524), ISBLANK(H524), ISBLANK(I524), ISBLANK(J524) ), "", 1.5*SQRT( EXP(2.21*(F524-1)) + EXP(2.21*(G524-1)) + EXP(2.21*(H524-1)) + EXP(2.21*(I524-1)) + EXP(2.21*J524) )/100*2.45 ) -> 0.35859414
A525: Intentionally produced microparticles | B525: 2020 | C525: EPS | D525: =Intentionally_produced_MPs!H57 -> 0 | E525: Information combined from: Scudo et al. (2017), Microplastics Annex XV Report (2020), and Statistics | Eurostat | F525: 1 | G525: 1 | H525: 3 | I525: 1 | J525: 1 | K525: =IF( OR( ISBLANK(F525),ISBLANK(G525), ISBLANK(H525), ISBLANK(I525), ISBLANK(J525) ), "", 1.5*SQRT( EXP(2.21*(F525-1)) + EXP(2.21*(G525-1)) + EXP(2.21*(H525-1)) + EXP(2.21*(I525-1)) + EXP(2.21*J525) )/100*2.45 ) -> 0.35859414
A526: Intentionally produced microparticles | B526: 2020 | C526: ABS | D526: =Intentionally_produced_MPs!M57 -> 0 | E526: Information combined from: Scudo et al. (2017), Microplastics Annex XV Report (2020), and Statistics | Eurostat | F526: 1 | G526: 1 | H526: 3 | I526: 1 | J526: 1 | K526: =IF( OR( ISBLANK(F526),ISBLANK(G526), ISBLANK(H526), ISBLANK(I526), ISBLANK(J526) ), "", 1.5*SQRT( EXP(2.21*(F526-1)) + EXP(2.21*(G526-1)) + EXP(2.21*(H526-1)) + EXP(2.21*(I526-1)) + EXP(2.21*J526) )/100*2.45 ) -> 0.35859414
A527: Intentionally produced microparticles | B527: 2020 | C527: PC | D527: =Intentionally_produced_MPs!O57 -> 0 | E527: Information combined from: Scudo et al. (2017), Microplastics Annex XV Report (2020), and Statistics | Eurostat | F527: 1 | G527: 1 | H527: 3 | I527: 1 | J527: 1 | K527: =IF( OR( ISBLANK(F527),ISBLANK(G527), ISBLANK(H527), ISBLANK(I527), ISBLANK(J527) ), "", 1.5*SQRT( EXP(2.21*(F527-1)) + EXP(2.21*(G527-1)) + EXP(2.21*(H527-1)) + EXP(2.21*(I527-1)) + EXP(2.21*J527) )/100*2.45 ) -> 0.35859414
A528: Intentionally produced microparticles | B528: 2020 | C528: PET | D528: =Intentionally_produced_MPs!J57 -> 0.60256976 | E528: Information combined from: Scudo et al. (2017), Microplastics Annex XV Report (2020), and Statistics | Eurostat | F528: 1 | G528: 1 | H528: 3 | I528: 1 | J528: 1 | K528: =IF( OR( ISBLANK(F528),ISBLANK(G528), ISBLANK(H528), ISBLANK(I528), ISBLANK(J528) ), "", 1.5*SQRT( EXP(2.21*(F528-1)) + EXP(2.21*(G528-1)) + EXP(2.21*(H528-1)) + EXP(2.21*(I528-1)) + EXP(2.21*J528) )/100*2.45 ) -> 0.35859414
A529: Intentionally produced microparticles | B529: 2020 | C529: PP | D529: =Intentionally_produced_MPs!F57 -> 1 | E529: Information combined from: Scudo et al. (2017), Microplastics Annex XV Report (2020), and Statistics | Eurostat | F529: 1 | G529: 1 | H529: 3 | I529: 1 | J529: 1 | K529: =IF( OR( ISBLANK(F529),ISBLANK(G529), ISBLANK(H529), ISBLANK(I529), ISBLANK(J529) ), "", 1.5*SQRT( EXP(2.21*(F529-1)) + EXP(2.21*(G529-1)) + EXP(2.21*(H529-1)) + EXP(2.21*(I529-1)) + EXP(2.21*J529) )/100*2.45 ) -> 0.35859414
A530: Intentionally produced microparticles | B530: 2020 | C530: LDPE | D530: =Intentionally_produced_MPs!D57 -> 1.125 | E530: Information combined from: Scudo et al. (2017), Microplastics Annex XV Report (2020), and Statistics | Eurostat | F530: 1 | G530: 1 | H530: 3 | I530: 1 | J530: 1 | K530: =IF( OR( ISBLANK(F530),ISBLANK(G530), ISBLANK(H530), ISBLANK(I530), ISBLANK(J530) ), "", 1.5*SQRT( EXP(2.21*(F530-1)) + EXP(2.21*(G530-1)) + EXP(2.21*(H530-1)) + EXP(2.21*(I530-1)) + EXP(2.21*J530) )/100*2.45 ) -> 0.35859414
A531: Intentionally produced microparticles | B531: 2020 | C531: PVC | D531: =Intentionally_produced_MPs!I57 -> 1.125 | E531: Information combined from: Scudo et al. (2017), Microplastics Annex XV Report (2020), and Statistics | Eurostat | F531: 1 | G531: 1 | H531: 3 | I531: 1 | J531: 1 | K531: =IF( OR( ISBLANK(F531),ISBLANK(G531), ISBLANK(H531), ISBLANK(I531), ISBLANK(J531) ), "", 1.5*SQRT( EXP(2.21*(F531-1)) + EXP(2.21*(G531-1)) + EXP(2.21*(H531-1)) + EXP(2.21*(I531-1)) + EXP(2.21*J531) )/100*2.45 ) -> 0.35859414
A532: Intentionally produced microparticles | B532: 2020 | C532: PMMA | D532: =Intentionally_produced_MPs!P57 -> 1.6025698 | E532: Information combined from: Scudo et al. (2017), Microplastics Annex XV Report (2020), and Statistics | Eurostat | F532: 1 | G532: 1 | H532: 3 | I532: 1 | J532: 1 | K532: =IF( OR( ISBLANK(F532),ISBLANK(G532), ISBLANK(H532), ISBLANK(I532), ISBLANK(J532) ), "", 1.5*SQRT( EXP(2.21*(F532-1)) + EXP(2.21*(G532-1)) + EXP(2.21*(H532-1)) + EXP(2.21*(I532-1)) + EXP(2.21*J532) )/100*2.45 ) -> 0.35859414
A533: Intentionally produced microparticles | B533: 2020 | C533: PA | D533: =Intentionally_produced_MPs!N57 -> 1.616339 | E533: Information combined from: Scudo et al. (2017), Microplastics Annex XV Report (2020), and Statistics | Eurostat | F533: 1 | G533: 1 | H533: 3 | I533: 1 | J533: 1 | K533: =IF( OR( ISBLANK(F533),ISBLANK(G533), ISBLANK(H533), ISBLANK(I533), ISBLANK(J533) ), "", 1.5*SQRT( EXP(2.21*(F533-1)) + EXP(2.21*(G533-1)) + EXP(2.21*(H533-1)) + EXP(2.21*(I533-1)) + EXP(2.21*J533) )/100*2.45 ) -> 0.35859414
A534: Intentionally produced microparticles | B534: 2020 | C534: HDPE | D534: =Intentionally_produced_MPs!E57 -> 8.4170263 | E534: Information combined from: Scudo et al. (2017), Microplastics Annex XV Report (2020), and Statistics | Eurostat | F534: 1 | G534: 1 | H534: 3 | I534: 1 | J534: 1 | K534: =IF( OR( ISBLANK(F534),ISBLANK(G534), ISBLANK(H534), ISBLANK(I534), ISBLANK(J534) ), "", 1.5*SQRT( EXP(2.21*(F534-1)) + EXP(2.21*(G534-1)) + EXP(2.21*(H534-1)) + EXP(2.21*(I534-1)) + EXP(2.21*J534) )/100*2.45 ) -> 0.35859414
A535: Intentionally produced microparticles | B535: 2020 | C535: OTHER | D535: =Intentionally_produced_MPs!Q57 -> 9.6628389 | E535: Information combined from: Scudo et al. (2017), Microplastics Annex XV Report (2020), and Statistics | Eurostat | F535: 1 | G535: 1 | H535: 3 | I535: 1 | J535: 1 | K535: =IF( OR( ISBLANK(F535),ISBLANK(G535), ISBLANK(H535), ISBLANK(I535), ISBLANK(J535) ), "", 1.5*SQRT( EXP(2.21*(F535-1)) + EXP(2.21*(G535-1)) + EXP(2.21*(H535-1)) + EXP(2.21*(I535-1)) + EXP(2.21*J535) )/100*2.45 ) -> 0.35859414
A536: Intentionally produced microparticles | B536: 2020 | C536: PUR | D536: =Intentionally_produced_MPs!L57 -> 21.948661 | E536: Information combined from: Scudo et al. (2017), Microplastics Annex XV Report (2020), and Statistics | Eurostat | F536: 1 | G536: 1 | H536: 3 | I536: 1 | J536: 1 | K536: =IF( OR( ISBLANK(F536),ISBLANK(G536), ISBLANK(H536), ISBLANK(I536), ISBLANK(J536) ), "", 1.5*SQRT( EXP(2.21*(F536-1)) + EXP(2.21*(G536-1)) + EXP(2.21*(H536-1)) + EXP(2.21*(I536-1)) + EXP(2.21*J536) )/100*2.45 ) -> 0.35859414
A537: Intentionally produced microparticles | B537: 2020 | C537: RUBBER | D537: =Intentionally_produced_MPs!K57 -> 115.5 | E537: Information combined from: Scudo et al. (2017), Microplastics Annex XV Report (2020), and Statistics | Eurostat | F537: 1 | G537: 1 | H537: 3 | I537: 1 | J537: 1 | K537: =IF( OR( ISBLANK(F537),ISBLANK(G537), ISBLANK(H537), ISBLANK(I537), ISBLANK(J537) ), "", 1.5*SQRT( EXP(2.21*(F537-1)) + EXP(2.21*(G537-1)) + EXP(2.21*(H537-1)) + EXP(2.21*(I537-1)) + EXP(2.21*J537) )/100*2.45 ) -> 0.35859414
A538: =Packaging!AF59 -> Packaging | B538: =Packaging!AG59 -> 2017 | C538: =Packaging!AI59 -> EPS | D538: =Packaging!AJ59 -> 196.16894 | E538: Data based on EUROSTAT, polymer distribution based on Cimpan et al. (2021) | F538: 1 | G538: 1 | H538: 2 | I538: 1 | J538: 2 | K538: =IF( OR( ISBLANK(F538),ISBLANK(G538), ISBLANK(H538), ISBLANK(I538), ISBLANK(J538) ), "", 1.5*SQRT( EXP(2.21*(F538-1)) + EXP(2.21*(G538-1)) + EXP(2.21*(H538-1)) + EXP(2.21*(I538-1)) + EXP(2.21*J538) )/100*2.45 ) -> 0.35859414
A539: =Packaging!AF51 -> Packaging | B539: =Packaging!AG51 -> 2018 | C539: =Packaging!AI51 -> EPS | D539: =Packaging!AJ51 -> 199.75023 | E539: Data based on EUROSTAT, polymer distribution based on Cimpan et al. (2021) | F539: 1 | G539: 1 | H539: 2 | I539: 1 | J539: 2 | K539: =IF( OR( ISBLANK(F539),ISBLANK(G539), ISBLANK(H539), ISBLANK(I539), ISBLANK(J539) ), "", 1.5*SQRT( EXP(2.21*(F539-1)) + EXP(2.21*(G539-1)) + EXP(2.21*(H539-1)) + EXP(2.21*(I539-1)) + EXP(2.21*J539) )/100*2.45 ) -> 0.35859414
...

Sheet Transfer coefficients
A1: From | B1: To | C1: Scale | D1: Material | E1: Data | F1: Priority | G1: Source | H1: Geo NL | I1: Geo EU | J1: Temp | K1: Mat | L1: Tech | M1: Rel | N1: Spread NL | O1: Spread EU | P1: Comments
A2: =Agriculture!A92 -> Agriculture | B2: =Agriculture!B92 -> Agricultural greenhouse films (discarded) | C2: =Agriculture!C92 -> NL | D2: =Agriculture!D92 -> PVC | E2: =Agriculture!E92 -> 0.062695658 | F2: =Agriculture!F92 -> 1 | G2: =Agriculture!G92 -> Urbanus, J.H., Brunner, A., Boersma, A., Henke, S., Kooter, I., Lensen, S., Parker, L., Schwarz, A., Imhof, P., Dortmans, A., Wijngaard, M., 2022. Autobanden, verpakkingen en landbouwfolie zijn in Nederland de grootste bronnen van microplastics. TNO. | H2: 1 | J2: 2 | K2: 1 | L2: 1 | M2: 2 | N2: =IF( OR( ISBLANK(H2),ISBLANK(J2), ISBLANK(K2), ISBLANK(L2), ISBLANK(M2) ), "", 1.5*SQRT( EXP(2.21*(H2-1)) + EXP(2.21*(J2-1)) + EXP(2.21*(K2-1)) + EXP(2.21*(L2-1)) + EXP(2.21*M2) )/100*2.45 ) -> 0.35859414 | O2: =IF( OR( ISBLANK(I2),ISBLANK(J2), ISBLANK(K2), ISBLANK(L2), ISBLANK(M2) ), "", 1.5*SQRT( EXP(2.21*(I2-1)) + EXP(2.21*(J2-1)) + EXP(2.21*(K2-1)) + EXP(2.21*(L2-1)) + EXP(2.21*M2) )/100*2.45 )
A3: =Agriculture!A93 -> Agriculture | B3: =Agriculture!B93 -> Agricultural greenhouse films (discarded) | C3: =Agriculture!C93 -> NL | D3: =Agriculture!D93 -> PS | E3: =Agriculture!E93 -> 0 | F3: =Agriculture!F93 -> 1 | G3: =Agriculture!G93 -> Urbanus, J.H., Brunner, A., Boersma, A., Henke, S., Kooter, I., Lensen, S., Parker, L., Schwarz, A., Imhof, P., Dortmans, A., Wijngaard, M., 2022. Autobanden, verpakkingen en landbouwfolie zijn in Nederland de grootste bronnen van microplastics. TNO. | H3: 1 | J3: 2 | K3: 1 | L3: 1 | M3: 2 | N3: =IF( OR( ISBLANK(H3),ISBLANK(J3), ISBLANK(K3), ISBLANK(L3), ISBLANK(M3) ), "", 1.5*SQRT( EXP(2.21*(H3-1)) + EXP(2.21*(J3-1)) + EXP(2.21*(K3-1)) + EXP(2.21*(L3-1)) + EXP(2.21*M3) )/100*2.45 ) -> 0.35859414 | O3: =IF( OR( ISBLANK(I3),ISBLANK(J3), ISBLANK(K3), ISBLANK(L3), ISBLANK(M3) ), "", 1.5*SQRT( EXP(2.21*(I3-1)) + EXP(2.21*(J3-1)) + EXP(2.21*(K3-1)) + EXP(2.21*(L3-1)) + EXP(2.21*M3) )/100*2.45 )
A4: =Agriculture!A94 -> Agriculture | B4: =Agriculture!B94 -> Agricultural greenhouse films (discarded) | C4: =Agriculture!C94 -> NL | D4: =Agriculture!D94 -> PP | E4: =Agriculture!E94 -> 0 | F4: =Agriculture!F94 -> 1 | G4: =Agriculture!G94 -> Urbanus, J.H., Brunner, A., Boersma, A., Henke, S., Kooter, I., Lensen, S., Parker, L., Schwarz, A., Imhof, P., Dortmans, A., Wijngaard, M., 2022. Autobanden, verpakkingen en landbouwfolie zijn in Nederland de grootste bronnen van microplastics. TNO. | H4: 1 | J4: 2 | K4: 1 | L4: 1 | M4: 2 | N4: =IF( OR( ISBLANK(H4),ISBLANK(J4), ISBLANK(K4), ISBLANK(L4), ISBLANK(M4) ), "", 1.5*SQRT( EXP(2.21*(H4-1)) + EXP(2.21*(J4-1)) + EXP(2.21*(K4-1)) + EXP(2.21*(L4-1)) + EXP(2.21*M4) )/100*2.45 ) -> 0.35859414 | O4: =IF( OR( ISBLANK(I4),ISBLANK(J4), ISBLANK(K4), ISBLANK(L4), ISBLANK(M4) ), "", 1.5*SQRT( EXP(2.21*(I4-1)) + EXP(2.21*(J4-1)) + EXP(2.21*(K4-1)) + EXP(2.21*(L4-1)) + EXP(2.21*M4) )/100*2.45 )
A5: =Agriculture!A95 -> Agriculture | B5: =Agriculture!B95 -> Agricultural greenhouse films (discarded) | C5: =Agriculture!C95 -> NL | D5: =Agriculture!D95 -> LDPE | E5: =Agriculture!E95 -> 0.13959893 | F5: =Agriculture!F95 -> 1 | G5: =Agriculture!G95 -> Urbanus, J.H., Brunner, A., Boersma, A., Henke, S., Kooter, I., Lensen, S., Parker, L., Schwarz, A., Imhof, P., Dortmans, A., Wijngaard, M., 2022. Autobanden, verpakkingen en landbouwfolie zijn in Nederland de grootste bronnen van microplastics. TNO. | H5: 1 | J5: 2 | K5: 1 | L5: 1 | M5: 2 | N5: =IF( OR( ISBLANK(H5),ISBLANK(J5), ISBLANK(K5), ISBLANK(L5), ISBLANK(M5) ), "", 1.5*SQRT( EXP(2.21*(H5-1)) + EXP(2.21*(J5-1)) + EXP(2.21*(K5-1)) + EXP(2.21*(L5-1)) + EXP(2.21*M5) )/100*2.45 ) -> 0.35859414 | O5: =IF( OR( ISBLANK(I5),ISBLANK(J5), ISBLANK(K5), ISBLANK(L5), ISBLANK(M5) ), "", 1.5*SQRT( EXP(2.21*(I5-1)) + EXP(2.21*(J5-1)) + EXP(2.21*(K5-1)) + EXP(2.21*(L5-1)) + EXP(2.21*M5) )/100*2.45 )
A6: =Agriculture!A96 -> Agriculture | B6: =Agriculture!B96 -> Agricultural greenhouse films (discarded) | C6: =Agriculture!C96 -> NL | D6: =Agriculture!D96 -> HDPE | E6: =Agriculture!E96 -> 0 | F6: =Agriculture!F96 -> 1 | G6: =Agriculture!G96 -> Urbanus, J.H., Brunner, A., Boersma, A., Henke, S., Kooter, I., Lensen, S., Parker, L., Schwarz, A., Imhof, P., Dortmans, A., Wijngaard, M., 2022. Autobanden, verpakkingen en landbouwfolie zijn in Nederland de grootste bronnen van microplastics. TNO. | H6: 1 | J6: 2 | K6: 1 | L6: 1 | M6: 2 | N6: =IF( OR( ISBLANK(H6),ISBLANK(J6), ISBLANK(K6), ISBLANK(L6), ISBLANK(M6) ), "", 1.5*SQRT( EXP(2.21*(H6-1)) + EXP(2.21*(J6-1)) + EXP(2.21*(K6-1)) + EXP(2.21*(L6-1)) + EXP(2.21*M6) )/100*2.45 ) -> 0.35859414 | O6: =IF( OR( ISBLANK(I6),ISBLANK(J6), ISBLANK(K6), ISBLANK(L6), ISBLANK(M6) ), "", 1.5*SQRT( EXP(2.21*(I6-1)) + EXP(2.21*(J6-1)) + EXP(2.21*(K6-1)) + EXP(2.21*(L6-1)) + EXP(2.21*M6) )/100*2.45 )
